5:return {{["x"] = 0, ["meta"] = {["fields"] = {}, ["inventory"] = {}}, ["y"] = 0, ["z"] = 0, ["name"] = "moreblocks:circle_stone_bricks"}, {["x"] = 0, ["meta"] = {["fields"] = {}, ["inventory"] = {}}, ["y"] = 0, ["z"] = 1, ["name"] = "moreblocks:circle_stone_bricks"}, {["x"] = 0, ["meta"] = {["fields"] = {}, ["inventory"] = {}}, ["y"] = 0, ["z"] = 2, ["name"] = "moreblocks:circle_stone_bricks"}, {["x"] = 0, ["meta"] = {["fields"] = {}, ["inventory"] = {}}, ["y"] = 0, ["z"] = 3, ["name"] = "moreblocks:circle_stone_bricks"}, {["x"] = 0, ["meta"] = {["fields"] = {}, ["inventory"] = {}}, ["y"] = 0, ["z"] = 4, ["name"] = "moreblocks:circle_stone_bricks"}, {["x"] = 0, ["meta"] = {["fields"] = {}, ["inventory"] = {}}, ["y"] = 1, ["z"] = 0, ["name"] = "moreblocks:circle_stone_bricks"}, {["x"] = 0, ["meta"] = {["fields"] = {}, ["inventory"] = {}}, ["y"] = 1, ["z"] = 1, ["name"] = "moreblocks:circle_stone_bricks"}, {["x"] = 0, ["meta"] = {["fields"] = {}, ["inventory"] = {}}, ["param2"] = 1, ["y"] = 1, ["param1"] = 174, ["z"] = 2, ["name"] = "scifi_nodes:door3a"}, {["x"] = 0, ["meta"] = {["fields"] = {}, ["inventory"] = {}}, ["y"] = 1, ["z"] = 3, ["name"] = "moreblocks:circle_stone_bricks"}, {["x"] = 0, ["meta"] = {["fields"] = {}, ["inventory"] = {}}, ["y"] = 1, ["z"] = 4, ["name"] = "moreblocks:circle_stone_bricks"}, {["x"] = 0, ["meta"] = {["fields"] = {}, ["inventory"] = {}}, ["y"] = 2, ["z"] = 0, ["name"] = "moreblocks:circle_stone_bricks"}, {["x"] = 0, ["meta"] = {["fields"] = {}, ["inventory"] = {}}, ["y"] = 2, ["z"] = 1, ["name"] = "moreblocks:circle_stone_bricks"}, {["x"] = 0, ["meta"] = {["fields"] = {}, ["inventory"] = {}}, ["param2"] = 1, ["y"] = 2, ["param1"] = 190, ["z"] = 2, ["name"] = "scifi_nodes:door3b"}, {["x"] = 0, ["meta"] = {["fields"] = {}, ["inventory"] = {}}, ["y"] = 2, ["z"] = 3, ["name"] = "moreblocks:circle_stone_bricks"}, {["x"] = 0, ["meta"] = {["fields"] = {}, ["inventory"] = {}}, ["y"] = 2, ["z"] = 4, ["name"] = "moreblocks:circle_stone_bricks"}, {["x"] = 0, ["meta"] = {["fields"] = {}, ["inventory"] = {}}, ["y"] = 3, ["z"] = 0, ["name"] = "moreblocks:circle_stone_bricks"}, {["x"] = 0, ["meta"] = {["fields"] = {}, ["inventory"] = {}}, ["y"] = 3, ["z"] = 1, ["name"] = "moreblocks:circle_stone_bricks"}, {["x"] = 0, ["meta"] = {["fields"] = {}, ["inventory"] = {}}, ["y"] = 3, ["z"] = 2, ["name"] = "moreblocks:circle_stone_bricks"}, {["x"] = 0, ["meta"] = {["fields"] = {}, ["inventory"] = {}}, ["y"] = 3, ["z"] = 3, ["name"] = "moreblocks:circle_stone_bricks"}, {["x"] = 0, ["meta"] = {["fields"] = {}, ["inventory"] = {}}, ["y"] = 3, ["z"] = 4, ["name"] = "moreblocks:circle_stone_bricks"}, {["x"] = 0, ["meta"] = {["fields"] = {}, ["inventory"] = {}}, ["y"] = 4, ["z"] = 0, ["name"] = "moreblocks:circle_stone_bricks"}, {["x"] = 0, ["meta"] = {["fields"] = {}, ["inventory"] = {}}, ["y"] = 4, ["z"] = 1, ["name"] = "moreblocks:circle_stone_bricks"}, {["x"] = 0, ["meta"] = {["fields"] = {}, ["inventory"] = {}}, ["y"] = 4, ["z"] = 2, ["name"] = "moreblocks:circle_stone_bricks"}, {["x"] = 0, ["meta"] = {["fields"] = {}, ["inventory"] = {}}, ["y"] = 4, ["z"] = 3, ["name"] = "moreblocks:circle_stone_bricks"}, {["x"] = 0, ["meta"] = {["fields"] = {}, ["inventory"] = {}}, ["y"] = 4, ["z"] = 4, ["name"] = "moreblocks:circle_stone_bricks"}, {["x"] = 1, ["meta"] = {["fields"] = {}, ["inventory"] = {}}, ["y"] = 0, ["z"] = 0, ["name"] = "moreblocks:circle_stone_bricks"}, {["x"] = 1, ["meta"] = {["fields"] = {}, ["inventory"] = {}}, ["y"] = 0, ["z"] = 1, ["name"] = "moreblocks:circle_stone_bricks"}, {["x"] = 1, ["meta"] = {["fields"] = {}, ["inventory"] = {}}, ["y"] = 0, ["z"] = 2, ["name"] = "moreblocks:circle_stone_bricks"}, {["x"] = 1, ["meta"] = {["fields"] = {}, ["inventory"] = {}}, ["y"] = 0, ["z"] = 3, ["name"] = "moreblocks:circle_stone_bricks"}, {["x"] = 1, ["meta"] = {["fields"] = {}, ["inventory"] = {}}, ["y"] = 0, ["z"] = 4, ["name"] = "moreblocks:circle_stone_bricks"}, {["x"] = 1, ["meta"] = {["fields"] = {}, ["inventory"] = {}}, ["y"] = 1, ["param1"] = 158, ["z"] = 0, ["name"] = "framedglass:steel_framed_obsidian_glass"}, {["x"] = 1, ["meta"] = {["fields"] = {["timestamp"] = "1543352649", ["station_network"] = "net1", ["infotext"] = "Station 'mobile' on travelnet 'net1' (owned by admin) ready for usage. Right-click to travel, punch to update.", ["formspec"] = "size[12,10]label[3.3,0.0;Travelnet-Box:]label[6.3,0.0;Punch box to update target list.]label[0.3,0.4;Name of this station:]label[6.3,0.4;mobile]label[0.3,0.8;Assigned to Network:]label[6.3,0.8;net1]label[0.3,1.2;Owned by:]label[6.3,1.2;admin]label[3.3,1.6;Click on target to travel there:]button_exit[4,2.5;4,0.5;target;base]button_exit[4,3.5;1,0.5;open_door;<>]label[4.9,3.35;mobile]label[8.0,1.6;Position in list:]button_exit[11.3,0.0;1.0,0.5;station_exit;Exit]button[9.6,1.6;1.4,0.5;move_up;move up]button[10.9,1.6;1.4,0.5;move_down;move down]", ["station_name"] = "mobile", ["owner"] = "admin"}, ["inventory"] = {}}, ["y"] = 1, ["param1"] = 173, ["z"] = 3, ["name"] = "travelnet:travelnet"}, {["x"] = 1, ["meta"] = {["fields"] = {}, ["inventory"] = {}}, ["y"] = 1, ["param1"] = 158, ["z"] = 4, ["name"] = "framedglass:steel_framed_obsidian_glass"}, {["x"] = 1, ["meta"] = {["fields"] = {}, ["inventory"] = {}}, ["y"] = 2, ["param1"] = 174, ["z"] = 0, ["name"] = "framedglass:steel_framed_obsidian_glass"}, {["x"] = 1, ["meta"] = {["fields"] = {}, ["inventory"] = {}}, ["y"] = 2, ["param1"] = 174, ["z"] = 4, ["name"] = "framedglass:steel_framed_obsidian_glass"}, {["x"] = 1, ["meta"] = {["fields"] = {}, ["inventory"] = {}}, ["y"] = 3, ["param1"] = 158, ["z"] = 0, ["name"] = "framedglass:steel_framed_obsidian_glass"}, {["x"] = 1, ["meta"] = {["fields"] = {}, ["inventory"] = {}}, ["y"] = 3, ["param1"] = 173, ["z"] = 1, ["name"] = "technic:hv_cable"}, {["x"] = 1, ["meta"] = {["fields"] = {}, ["inventory"] = {}}, ["y"] = 3, ["param1"] = 189, ["z"] = 2, ["name"] = "technic:hv_cable"}, {["x"] = 1, ["meta"] = {["fields"] = {}, ["inventory"] = {}}, ["y"] = 3, ["param1"] = 173, ["z"] = 3, ["name"] = "technic:hv_cable"}, {["x"] = 1, ["meta"] = {["fields"] = {}, ["inventory"] = {}}, ["y"] = 3, ["param1"] = 158, ["z"] = 4, ["name"] = "framedglass:steel_framed_obsidian_glass"}, {["x"] = 1, ["meta"] = {["fields"] = {}, ["inventory"] = {}}, ["y"] = 4, ["z"] = 0, ["name"] = "moreblocks:circle_stone_bricks"}, {["x"] = 1, ["meta"] = {["fields"] = {["HV_EU_input"] = "0", ["HV_network"] = "(-26657,264,20)", ["infotext"] = "Arrayed Solar HV Generator Active (5000 EU)", ["HV_EU_timeout"] = "2", ["HV_EU_supply"] = "5000"}, ["inventory"] = {}}, ["y"] = 4, ["param1"] = 158, ["z"] = 1, ["name"] = "technic:solar_array_hv"}, {["x"] = 1, ["meta"] = {["fields"] = {["HV_EU_input"] = "0", ["HV_network"] = "(-26657,264,20)", ["infotext"] = "Arrayed Solar HV Generator Active (5000 EU)", ["HV_EU_timeout"] = "2", ["HV_EU_supply"] = "5000"}, ["inventory"] = {}}, ["y"] = 4, ["param1"] = 174, ["z"] = 2, ["name"] = "technic:solar_array_hv"}, {["x"] = 1, ["meta"] = {["fields"] = {["HV_EU_input"] = "0", ["HV_network"] = "(-26657,264,20)", ["infotext"] = "Arrayed Solar HV Generator Active (5000 EU)", ["HV_EU_timeout"] = "2", ["HV_EU_supply"] = "5000"}, ["inventory"] = {}}, ["y"] = 4, ["param1"] = 158, ["z"] = 3, ["name"] = "technic:solar_array_hv"}, {["x"] = 1, ["meta"] = {["fields"] = {}, ["inventory"] = {}}, ["y"] = 4, ["z"] = 4, ["name"] = "moreblocks:circle_stone_bricks"}, {["x"] = 2, ["meta"] = {["fields"] = {}, ["inventory"] = {}}, ["y"] = 0, ["z"] = 0, ["name"] = "moreblocks:circle_stone_bricks"}, {["x"] = 2, ["meta"] = {["fields"] = {}, ["inventory"] = {}}, ["y"] = 0, ["z"] = 1, ["name"] = "moreblocks:circle_stone_bricks"}, {["x"] = 2, ["meta"] = {["fields"] = {}, ["inventory"] = {}}, ["y"] = 0, ["z"] = 2, ["name"] = "moreblocks:circle_stone_bricks"}, {["x"] = 2, ["meta"] = {["fields"] = {}, ["inventory"] = {}}, ["y"] = 0, ["z"] = 3, ["name"] = "moreblocks:circle_stone_bricks"}, {["x"] = 2, ["meta"] = {["fields"] = {}, ["inventory"] = {}}, ["y"] = 0, ["z"] = 4, ["name"] = "moreblocks:circle_stone_bricks"}, {["x"] = 2, ["meta"] = {["fields"] = {}, ["inventory"] = {}}, ["y"] = 1, ["param1"] = 174, ["z"] = 0, ["name"] = "framedglass:steel_framed_obsidian_glass"}, {["x"] = 2, ["meta"] = {["fields"] = {}, ["inventory"] = {}}, ["y"] = 1, ["param1"] = 204, ["z"] = 2, ["name"] = "technic:hv_cable"}, {["x"] = 2, ["meta"] = {["fields"] = {}, ["inventory"] = {}}, ["y"] = 1, ["param1"] = 174, ["z"] = 4, ["name"] = "framedglass:steel_framed_obsidian_glass"}, {["x"] = 2, ["meta"] = {["fields"] = {}, ["inventory"] = {}}, ["y"] = 2, ["param1"] = 190, ["z"] = 0, ["name"] = "framedglass:steel_framed_obsidian_glass"}, {["x"] = 2, ["meta"] = {["fields"] = {["HV_EU_input"] = "0", ["HV_network"] = "(-26657,264,20)", ["formspec"] = "size[8,10;]field[0,1;2,1;x;X;-26658]field[2,1;2,1;y;Y;264]field[4,1;2,1;z;Z;20]field[6,1;2,1;radius;Radius;2]button_exit[0,2;2,1;jump;Jump]button_exit[2,2;2,1;show;Show]button_exit[4,2;2,1;save;Save]button[6,2;2,1;reset;Reset]list[context;main;0,3;8,1;]button[0,4;4,1;write_book;Write to book]button[4,4;4,1;read_book;Read from book]list[current_player;main;0,5;8,4;]listring[]", ["y"] = "264", ["owner"] = "admin", ["powerstorage"] = "1000000", ["HV_EU_demand"] = "0", ["radius"] = "2", ["infotext"] = "Power: 0/0 Store: 1000000", ["HV_EU_timeout"] = "2", ["z"] = "20", ["x"] = "-26658"}, ["inventory"] = {["main"] = {"default:book 98", "", "", "", "", "", "", ""}}}, ["y"] = 2, ["z"] = 2, ["name"] = "jumpdrive:engine"}, {["x"] = 2, ["meta"] = {["fields"] = {}, ["inventory"] = {}}, ["y"] = 2, ["z"] = 3, ["name"] = "locator:radar"}, {["x"] = 2, ["meta"] = {["fields"] = {}, ["inventory"] = {}}, ["y"] = 2, ["param1"] = 158, ["z"] = 4, ["name"] = "framedglass:steel_framed_obsidian_glass"}, {["x"] = 2, ["meta"] = {["fields"] = {}, ["inventory"] = {}}, ["y"] = 3, ["param1"] = 174, ["z"] = 0, ["name"] = "framedglass:steel_framed_obsidian_glass"}, {["x"] = 2, ["meta"] = {["fields"] = {}, ["inventory"] = {}}, ["y"] = 3, ["param1"] = 189, ["z"] = 1, ["name"] = "technic:hv_cable"}, {["x"] = 2, ["meta"] = {["fields"] = {}, ["inventory"] = {}}, ["y"] = 3, ["param1"] = 205, ["z"] = 2, ["name"] = "technic:hv_cable"}, {["x"] = 2, ["meta"] = {["fields"] = {}, ["inventory"] = {}}, ["y"] = 3, ["param1"] = 189, ["z"] = 3, ["name"] = "technic:hv_cable"}, {["x"] = 2, ["meta"] = {["fields"] = {}, ["inventory"] = {}}, ["y"] = 3, ["param1"] = 174, ["z"] = 4, ["name"] = "framedglass:steel_framed_obsidian_glass"}, {["x"] = 2, ["meta"] = {["fields"] = {}, ["inventory"] = {}}, ["y"] = 4, ["z"] = 0, ["name"] = "moreblocks:circle_stone_bricks"}, {["x"] = 2, ["meta"] = {["fields"] = {["HV_EU_input"] = "0", ["HV_network"] = "(-26657,264,20)", ["infotext"] = "Arrayed Solar HV Generator Active (5000 EU)", ["HV_EU_timeout"] = "2", ["HV_EU_supply"] = "5000"}, ["inventory"] = {}}, ["y"] = 4, ["param1"] = 174, ["z"] = 1, ["name"] = "technic:solar_array_hv"}, {["x"] = 2, ["meta"] = {["fields"] = {["HV_EU_input"] = "0", ["HV_network"] = "(-26657,264,20)", ["infotext"] = "Arrayed Solar HV Generator Active (5000 EU)", ["HV_EU_timeout"] = "2", ["HV_EU_supply"] = "5000"}, ["inventory"] = {}}, ["y"] = 4, ["param1"] = 190, ["z"] = 2, ["name"] = "technic:solar_array_hv"}, {["x"] = 2, ["meta"] = {["fields"] = {["HV_EU_input"] = "0", ["HV_network"] = "(-26657,264,20)", ["infotext"] = "Arrayed Solar HV Generator Active (5000 EU)", ["HV_EU_timeout"] = "2", ["HV_EU_supply"] = "5000"}, ["inventory"] = {}}, ["y"] = 4, ["param1"] = 174, ["z"] = 3, ["name"] = "technic:solar_array_hv"}, {["x"] = 2, ["meta"] = {["fields"] = {}, ["inventory"] = {}}, ["y"] = 4, ["z"] = 4, ["name"] = "moreblocks:circle_stone_bricks"}, {["x"] = 3, ["meta"] = {["fields"] = {}, ["inventory"] = {}}, ["y"] = 0, ["z"] = 0, ["name"] = "moreblocks:circle_stone_bricks"}, {["x"] = 3, ["meta"] = {["fields"] = {}, ["inventory"] = {}}, ["y"] = 0, ["z"] = 1, ["name"] = "moreblocks:circle_stone_bricks"}, {["x"] = 3, ["meta"] = {["fields"] = {}, ["inventory"] = {}}, ["y"] = 0, ["z"] = 2, ["name"] = "moreblocks:circle_stone_bricks"}, {["x"] = 3, ["meta"] = {["fields"] = {}, ["inventory"] = {}}, ["y"] = 0, ["z"] = 3, ["name"] = "moreblocks:circle_stone_bricks"}, {["x"] = 3, ["meta"] = {["fields"] = {}, ["inventory"] = {}}, ["y"] = 0, ["z"] = 4, ["name"] = "moreblocks:circle_stone_bricks"}, {["x"] = 3, ["meta"] = {["fields"] = {}, ["inventory"] = {}}, ["y"] = 1, ["param1"] = 158, ["z"] = 0, ["name"] = "framedglass:steel_framed_obsidian_glass"}, {["x"] = 3, ["meta"] = {["fields"] = {}, ["inventory"] = {}}, ["y"] = 1, ["param1"] = 173, ["z"] = 1, ["name"] = "technic:hv_cable"}, {["x"] = 3, ["meta"] = {["fields"] = {}, ["inventory"] = {}}, ["y"] = 1, ["param1"] = 189, ["z"] = 2, ["name"] = "technic:hv_cable"}, {["x"] = 3, ["meta"] = {["fields"] = {}, ["inventory"] = {}}, ["y"] = 1, ["param1"] = 173, ["z"] = 3, ["name"] = "technic:hv_cable"}, {["x"] = 3, ["meta"] = {["fields"] = {}, ["inventory"] = {}}, ["y"] = 1, ["param1"] = 158, ["z"] = 4, ["name"] = "framedglass:steel_framed_obsidian_glass"}, {["x"] = 3, ["meta"] = {["fields"] = {}, ["inventory"] = {}}, ["y"] = 2, ["param1"] = 174, ["z"] = 0, ["name"] = "framedglass:steel_framed_obsidian_glass"}, {["x"] = 3, ["meta"] = {["fields"] = {}, ["inventory"] = {}}, ["y"] = 2, ["param1"] = 189, ["z"] = 1, ["name"] = "technic:hv_cable"}, {["x"] = 3, ["meta"] = {["fields"] = {["HV_EU_input"] = "0", ["active"] = "1", ["formspec"] = "field[channel;Channel;${channel}]", ["supply"] = "45000", ["channel"] = "switching_station(-26657,264,20)", ["demand"] = "0", ["HV_EU_timeout"] = "0", ["HV_network"] = "(-26657,264,20)", ["infotext"] = "Switching Station. Supply: 45 kEU Demand: 0 EU"}, ["inventory"] = {}}, ["y"] = 2, ["z"] = 2, ["name"] = "technic:switching_station"}, {["x"] = 3, ["meta"] = {["fields"] = {["HV_EU_input"] = "0", ["HV_network"] = "(-26657,264,20)", ["formspec"] = "size[8,9]image[1,1;1,2;technic_power_meter_bg.png]list[context;src;3,1;1,1;]image[4,1;1,1;technic_battery_reload.png]list[context;dst;5,1;1,1;]label[0,0;HV Battery Box]label[3,0;Charge]label[5,0;Discharge]label[1,3;Power level]list[current_player;main;0,5;8,4;]listring[context;dst]listring[current_player;main]listring[context;src]listring[current_player;main]button[0.6,3.7;2,1;edit_channel;edit Channel]list[context;upgrade1;3.5,3;1,1;]list[context;upgrade2;4.5,3;1,1;]label[3.5,4;Upgrade Slots]listring[context;upgrade1]listring[current_player;main]listring[context;upgrade2]listring[current_player;main]image[1,1;1,2;technic_power_meter_bg.png^[lowpart:100:technic_power_meter_fg.png]image_button[3,2.0;1,0.6;pipeworks_button_off.png;fs_helpers_cycling:1:split_src_stacks;;false;false;pipeworks_button_interm.png]label[3.9,2.01;Allow splitting incoming 'charge' stacks from tubes]image_button[3,2.5;1,0.6;pipeworks_button_off.png;fs_helpers_cycling:1:split_dst_stacks;;false;false;pipeworks_button_interm.png]label[3.9,2.51;Allow splitting incoming 'discharge' stacks]", ["internal_EU_charge"] = "1000000", ["HV_EU_supply"] = "400000", ["tube_time"] = "0", ["HV_EU_demand"] = "0", ["infotext"] = "HV Battery Box: 1000 kEU / 1000 kEU Idle", ["HV_EU_timeout"] = "1", ["last_side_shown"] = "8", ["channel"] = "hv_battery_box(-26657,264,21)"}, ["inventory"] = {["upgrade2"] = {""}, ["src"] = {""}, ["upgrade1"] = {""}, ["dst"] = {""}}}, ["param2"] = 1, ["y"] = 2, ["z"] = 3, ["name"] = "technic:hv_battery_box8"}, {["x"] = 3, ["meta"] = {["fields"] = {}, ["inventory"] = {}}, ["y"] = 2, ["param1"] = 142, ["z"] = 4, ["name"] = "framedglass:steel_framed_obsidian_glass"}, {["x"] = 3, ["meta"] = {["fields"] = {}, ["inventory"] = {}}, ["y"] = 3, ["param1"] = 158, ["z"] = 0, ["name"] = "framedglass:steel_framed_obsidian_glass"}, {["x"] = 3, ["meta"] = {["fields"] = {}, ["inventory"] = {}}, ["y"] = 3, ["param1"] = 173, ["z"] = 1, ["name"] = "technic:hv_cable"}, {["x"] = 3, ["meta"] = {["fields"] = {}, ["inventory"] = {}}, ["y"] = 3, ["param1"] = 189, ["z"] = 2, ["name"] = "technic:hv_cable"}, {["x"] = 3, ["meta"] = {["fields"] = {}, ["inventory"] = {}}, ["y"] = 3, ["param1"] = 173, ["z"] = 3, ["name"] = "technic:hv_cable"}, {["x"] = 3, ["meta"] = {["fields"] = {}, ["inventory"] = {}}, ["y"] = 3, ["param1"] = 158, ["z"] = 4, ["name"] = "framedglass:steel_framed_obsidian_glass"}, {["x"] = 3, ["meta"] = {["fields"] = {}, ["inventory"] = {}}, ["y"] = 4, ["z"] = 0, ["name"] = "moreblocks:circle_stone_bricks"}, {["x"] = 3, ["meta"] = {["fields"] = {["HV_EU_input"] = "0", ["HV_network"] = "(-26657,264,20)", ["infotext"] = "Arrayed Solar HV Generator Active (5000 EU)", ["HV_EU_timeout"] = "1", ["HV_EU_supply"] = "5000"}, ["inventory"] = {}}, ["y"] = 4, ["param1"] = 158, ["z"] = 1, ["name"] = "technic:solar_array_hv"}, {["x"] = 3, ["meta"] = {["fields"] = {["HV_EU_input"] = "0", ["HV_network"] = "(-26657,264,20)", ["infotext"] = "Arrayed Solar HV Generator Active (5000 EU)", ["HV_EU_timeout"] = "1", ["HV_EU_supply"] = "5000"}, ["inventory"] = {}}, ["y"] = 4, ["param1"] = 174, ["z"] = 2, ["name"] = "technic:solar_array_hv"}, {["x"] = 3, ["meta"] = {["fields"] = {["HV_EU_input"] = "0", ["HV_network"] = "(-26657,264,20)", ["infotext"] = "Arrayed Solar HV Generator Active (5000 EU)", ["HV_EU_timeout"] = "1", ["HV_EU_supply"] = "5000"}, ["inventory"] = {}}, ["y"] = 4, ["param1"] = 158, ["z"] = 3, ["name"] = "technic:solar_array_hv"}, {["x"] = 3, ["meta"] = {["fields"] = {}, ["inventory"] = {}}, ["y"] = 4, ["z"] = 4, ["name"] = "moreblocks:circle_stone_bricks"}, {["x"] = 4, ["meta"] = {["fields"] = {}, ["inventory"] = {}}, ["y"] = 0, ["z"] = 0, ["name"] = "moreblocks:circle_stone_bricks"}, {["x"] = 4, ["meta"] = {["fields"] = {}, ["inventory"] = {}}, ["y"] = 0, ["z"] = 1, ["name"] = "moreblocks:circle_stone_bricks"}, {["x"] = 4, ["meta"] = {["fields"] = {}, ["inventory"] = {}}, ["y"] = 0, ["z"] = 2, ["name"] = "moreblocks:circle_stone_bricks"}, {["x"] = 4, ["meta"] = {["fields"] = {}, ["inventory"] = {}}, ["y"] = 0, ["z"] = 3, ["name"] = "moreblocks:circle_stone_bricks"}, {["x"] = 4, ["meta"] = {["fields"] = {}, ["inventory"] = {}}, ["y"] = 0, ["z"] = 4, ["name"] = "moreblocks:circle_stone_bricks"}, {["x"] = 4, ["meta"] = {["fields"] = {}, ["inventory"] = {}}, ["y"] = 1, ["z"] = 0, ["name"] = "moreblocks:circle_stone_bricks"}, {["x"] = 4, ["meta"] = {["fields"] = {}, ["inventory"] = {}}, ["y"] = 1, ["param1"] = 158, ["z"] = 1, ["name"] = "framedglass:steel_framed_obsidian_glass"}, {["x"] = 4, ["meta"] = {["fields"] = {}, ["inventory"] = {}}, ["y"] = 1, ["param1"] = 174, ["z"] = 2, ["name"] = "framedglass:steel_framed_obsidian_glass"}, {["x"] = 4, ["meta"] = {["fields"] = {}, ["inventory"] = {}}, ["y"] = 1, ["param1"] = 158, ["z"] = 3, ["name"] = "framedglass:steel_framed_obsidian_glass"}, {["x"] = 4, ["meta"] = {["fields"] = {}, ["inventory"] = {}}, ["y"] = 1, ["z"] = 4, ["name"] = "moreblocks:circle_stone_bricks"}, {["x"] = 4, ["meta"] = {["fields"] = {}, ["inventory"] = {}}, ["y"] = 2, ["z"] = 0, ["name"] = "moreblocks:circle_stone_bricks"}, {["x"] = 4, ["meta"] = {["fields"] = {}, ["inventory"] = {}}, ["y"] = 2, ["param1"] = 174, ["z"] = 1, ["name"] = "framedglass:steel_framed_obsidian_glass"}, {["x"] = 4, ["meta"] = {["fields"] = {}, ["inventory"] = {}}, ["y"] = 2, ["param1"] = 158, ["z"] = 2, ["name"] = "framedglass:steel_framed_obsidian_glass"}, {["x"] = 4, ["meta"] = {["fields"] = {}, ["inventory"] = {}}, ["y"] = 2, ["param1"] = 142, ["z"] = 3, ["name"] = "framedglass:steel_framed_obsidian_glass"}, {["x"] = 4, ["meta"] = {["fields"] = {}, ["inventory"] = {}}, ["y"] = 2, ["z"] = 4, ["name"] = "moreblocks:circle_stone_bricks"}, {["x"] = 4, ["meta"] = {["fields"] = {}, ["inventory"] = {}}, ["y"] = 3, ["z"] = 0, ["name"] = "moreblocks:circle_stone_bricks"}, {["x"] = 4, ["meta"] = {["fields"] = {}, ["inventory"] = {}}, ["y"] = 3, ["param1"] = 158, ["z"] = 1, ["name"] = "framedglass:steel_framed_obsidian_glass"}, {["x"] = 4, ["meta"] = {["fields"] = {}, ["inventory"] = {}}, ["y"] = 3, ["param1"] = 174, ["z"] = 2, ["name"] = "framedglass:steel_framed_obsidian_glass"}, {["x"] = 4, ["meta"] = {["fields"] = {}, ["inventory"] = {}}, ["y"] = 3, ["param1"] = 158, ["z"] = 3, ["name"] = "framedglass:steel_framed_obsidian_glass"}, {["x"] = 4, ["meta"] = {["fields"] = {}, ["inventory"] = {}}, ["y"] = 3, ["z"] = 4, ["name"] = "moreblocks:circle_stone_bricks"}, {["x"] = 4, ["meta"] = {["fields"] = {}, ["inventory"] = {}}, ["y"] = 4, ["z"] = 0, ["name"] = "moreblocks:circle_stone_bricks"}, {["x"] = 4, ["meta"] = {["fields"] = {}, ["inventory"] = {}}, ["y"] = 4, ["z"] = 1, ["name"] = "moreblocks:circle_stone_bricks"}, {["x"] = 4, ["meta"] = {["fields"] = {}, ["inventory"] = {}}, ["y"] = 4, ["z"] = 2, ["name"] = "moreblocks:circle_stone_bricks"}, {["x"] = 4, ["meta"] = {["fields"] = {}, ["inventory"] = {}}, ["y"] = 4, ["z"] = 3, ["name"] = "moreblocks:circle_stone_bricks"}, {["x"] = 4, ["meta"] = {["fields"] = {}, ["inventory"] = {}}, ["y"] = 4, ["z"] = 4, ["name"] = "moreblocks:circle_stone_bricks"}}